<?xml version="1.0"?>
<robot xmlns:xacro="http://ros.org/wiki/xacro">
  <xacro:include filename="$(find abb_resources)/urdf/common_materials.xacro"/>

  <xacro:macro name="abb_irb4400l_30_243" params="prefix">
    <!-- link list -->
    <link name="${prefix}base_link">
      <visual>
        <origin xyz="0 0 0" rpy="0 0 0"/>
        <geometry>
          <mesh filename="package://abb_irb4400_support/meshes/irb4400l_30_243/visual/base_link.stl"/>
        </geometry>
        <xacro:material_abb_orange />
      </visual>
      <collision>
        <geometry>
          <mesh filename="package://abb_irb4400_support/meshes/irb4400l_30_243/collision/base_link.stl"/>
        </geometry>
        <xacro:material_abb_yellow />
      </collision>
    </link>
    <link name="${prefix}link_1">
      <visual>
        <origin xyz="0 0 0" rpy="0 0 0"/>
        <geometry>
          <mesh filename="package://abb_irb4400_support/meshes/irb4400l_30_243/visual/link_1.stl"/>
        </geometry>
        <xacro:material_abb_orange />
      </visual>
      <collision>
        <origin xyz="0 0 0" rpy="0 0 0"/>
        <geometry>
          <mesh filename="package://abb_irb4400_support/meshes/irb4400l_30_243/collision/link_1.stl"/>
        </geometry>
        <xacro:material_abb_yellow />
      </collision>
    </link>
    <link name="${prefix}link_2">
      <visual>
        <origin xyz="0 0 0" rpy="0 0 0"/>
        <geometry>
          <mesh filename="package://abb_irb4400_support/meshes/irb4400l_30_243/visual/link_2.stl"/>
        </geometry>
        <xacro:material_abb_orange />
      </visual>
      <collision>
        <origin xyz="0 0 0" rpy="0 0 0"/>
        <geometry>
          <mesh filename="package://abb_irb4400_support/meshes/irb4400l_30_243/collision/link_2.stl"/>
        </geometry>
        <xacro:material_abb_yellow />
      </collision>
    </link>
    <link name="${prefix}link_3">
      <visual>
        <origin xyz="0 0 0" rpy="0 0 0"/>
        <geometry>
          <mesh filename="package://abb_irb4400_support/meshes/irb4400l_30_243/visual/link_3.stl"/>
        </geometry>
        <xacro:material_abb_orange />
      </visual>
      <collision>
        <origin xyz="0 0 0" rpy="0 0 0"/>
        <geometry>
          <mesh filename="package://abb_irb4400_support/meshes/irb4400l_30_243/collision/link_3.stl"/>
        </geometry>
        <xacro:material_abb_yellow />
      </collision>
    </link>
    <link name="${prefix}link_4">
      <visual>
        <origin xyz="0 0 0" rpy="0 0 0"/>
        <geometry>
          <mesh filename="package://abb_irb4400_support/meshes/irb4400l_30_243/visual/link_4.stl"/>
        </geometry>
        <xacro:material_abb_orange />
      </visual>
      <collision>
        <origin xyz="0 0 0" rpy="0 0 0"/>
        <geometry>
          <mesh filename="package://abb_irb4400_support/meshes/irb4400l_30_243/collision/link_4.stl"/>
        </geometry>
        <xacro:material_abb_yellow />
      </collision>
    </link>
    <link name="${prefix}link_5">
      <visual>
        <origin xyz="0 0 0" rpy="0 0 0"/>
        <geometry>
          <mesh filename="package://abb_irb4400_support/meshes/irb4400l_30_243/visual/link_5.stl"/>
        </geometry>
        <xacro:material_abb_orange />
      </visual>
      <collision>
        <origin xyz="0 0 0" rpy="0 0 0"/>
        <geometry>
          <mesh filename="package://abb_irb4400_support/meshes/irb4400l_30_243/collision/link_5.stl"/>
        </geometry>
        <xacro:material_abb_yellow />
      </collision>
    </link>
    <link name="${prefix}link_6">
      <visual>
        <origin xyz="0 0 0" rpy="0 0 0"/>
        <geometry>
          <mesh filename="package://abb_irb4400_support/meshes/irb4400l_30_243/visual/link_6.stl"/>
        </geometry>
        <xacro:material_abb_black />
      </visual>
      <collision>
        <origin xyz="0 0 0" rpy="0 0 0"/>
        <geometry>
          <mesh filename="package://abb_irb4400_support/meshes/irb4400l_30_243/collision/link_6.stl"/>
        </geometry>
        <xacro:material_abb_yellow />
      </collision>
    </link>
    <link name="${prefix}tool0"/>
    <!-- end of link list -->

    <!-- joint list -->
    <joint name="${prefix}joint_1" type="revolute">
      <origin xyz="0 0 0" rpy="0 0 0"/>
      <parent link="${prefix}base_link"/>
      <child link="${prefix}link_1"/>
      <axis xyz="0 0 1"/>
      <limit effort="0" lower="-2.87979" upper="2.87979" velocity="2.618"/>
    </joint>
    <joint name="${prefix}joint_2" type="revolute">
      <origin xyz="0.2 0 0.68" rpy="0 0 0"/>
      <parent link="${prefix}link_1"/>
      <child link="${prefix}link_2"/>
      <axis xyz="0 1 0"/>
      <limit effort="0" lower="-1.2217" upper="1.658" velocity="2.0944"/>
      </joint>
    <joint name="${prefix}joint_3" type="revolute">
      <origin xyz="0 0 0.89" rpy="0 0 0"/>
      <parent link="${prefix}link_2"/>
      <child link="${prefix}link_3"/>
      <axis xyz="0 1 0"/>
      <limit effort="0" lower="-1.0472" upper="1.1345" velocity="2.0944"/>
    </joint>
    <joint name="${prefix}joint_4" type="revolute">
      <origin xyz="1.38 0 0.15" rpy="0 0 0"/>
      <parent link="${prefix}link_3"/>
      <child link="${prefix}link_4"/>
      <axis xyz="1 0 0"/>
      <limit effort="0" lower="-3.49" upper="3.49" velocity="3.927"/>
    </joint>
    <joint name="${prefix}joint_5" type="revolute">
      <origin xyz="0 0 0" rpy="0 0 0"/>
      <parent link="${prefix}link_4"/>
      <child link="${prefix}link_5"/>
      <axis xyz="0 1 0"/>
      <limit effort="0" lower="-2.0944" upper="2.0944" velocity="4.3633"/>
    </joint>
    <joint name="${prefix}joint_6" type="revolute">
      <origin xyz="0 0 0" rpy="0 0 0"/>
      <parent link="${prefix}link_5"/>
      <child link="${prefix}link_6"/>
      <axis xyz="1 0 0"/>
      <limit effort="0" lower="-6.9813" upper="6.9813" velocity="5.7596"/>
    </joint>
    <joint name="${prefix}joint_6-tool0" type="fixed">
      <parent link="${prefix}link_6"/>
      <child link="${prefix}tool0"/>
      <origin xyz="0.14 0 0" rpy="0 0 0"/>
    </joint>
    <!-- end of joint list -->

    <!-- ROS base_link to ABB World Coordinates transform -->
    <link name="${prefix}base" />
    <joint name="${prefix}base_link-base" type="fixed">
      <origin xyz="0 0 0" rpy="0 0 0"/>
      <parent link="${prefix}base_link"/>
      <child link="${prefix}base"/>
    </joint>
  </xacro:macro>
</robot>
