<robot name="abb_irb4400" xmlns:xacro="http://ros.org/wiki/xacro">
  <link name="base_link">
    <visual>
      <geometry>
        <mesh filename="package://abb_irb4400_support/meshes/irb4400/visual/base_link.stl"/>
      </geometry>
      <material name="abb_orange">
        <color rgba="1 0.43 0 1"/>
      </material>
    </visual>
    <collision>
      <geometry>
        <mesh filename="package://abb_irb4400_support/meshes/irb4400/collision/base_link.stl"/>
      </geometry>
      <material name="yellow">
        <color rgba="0 1 1 1"/>
      </material>
    </collision>
  </link>
  <link name="link_1">
    <visual>
      <geometry>
        <mesh filename="package://abb_irb4400_support/meshes/irb4400/visual/link_1.stl"/>
      </geometry>
      <material name="abb_orange"/>
    </visual>
    <collision>
      <geometry>
        <mesh filename="package://abb_irb4400_support/meshes/irb4400/collision/link_1.stl"/>
      </geometry>
      <material name="yellow"/>
    </collision>
  </link>
  <link name="link_2">
    <visual>
      <geometry>
        <mesh filename="package://abb_irb4400_support/meshes/irb4400/visual/link_2.stl"/>
      </geometry>
      <material name="abb_orange"/>
    </visual>
    <collision>
      <geometry>
        <mesh filename="package://abb_irb4400_support/meshes/irb4400/collision/link_2.stl"/>
      </geometry>
      <material name="yellow"/>
    </collision>
  </link>
  <link name="link_3">
    <visual>
      <geometry>
        <mesh filename="package://abb_irb4400_support/meshes/irb4400/visual/link_3.stl"/>
      </geometry>
      <material name="abb_orange"/>
    </visual>
    <collision>
      <geometry>
        <mesh filename="package://abb_irb4400_support/meshes/irb4400/collision/link_3.stl"/>
      </geometry>
      <material name="yellow"/>
    </collision>
  </link>
  <link name="link_4">
    <visual>
      <geometry>
        <mesh filename="package://abb_irb4400_support/meshes/irb4400/visual/link_4.stl"/>
      </geometry>
      <material name="abb_orange"/>
    </visual>
    <collision>
      <geometry>
        <mesh filename="package://abb_irb4400_support/meshes/irb4400/collision/link_4.stl"/>
      </geometry>
      <material name="yellow"/>
    </collision>
  </link>
  <link name="link_5">
    <visual>
      <geometry>
        <mesh filename="package://abb_irb4400_support/meshes/irb4400/visual/link_5.stl"/>
      </geometry>
      <material name="abb_orange"/>
    </visual>
    <collision>
      <geometry>
        <mesh filename="package://abb_irb4400_support/meshes/irb4400/collision/link_5.stl"/>
      </geometry>
      <material name="yellow"/>
    </collision>
  </link>
  <link name="link_6">
    <visual>
      <geometry>
        <mesh filename="package://abb_irb4400_support/meshes/irb4400/visual/link_6.stl"/>
      </geometry>
      <material name="lt_black">
        <color rgba="0.3 0.3 0.3 1"/>
      </material>
    </visual>
    <collision>
      <geometry>
        <mesh filename="package://abb_irb4400_support/meshes/irb4400/collision/link_6.stl"/>
      </geometry>
      <material name="yellow"/>
    </collision>
  </link>
  <link name="tool0"/>
  <link name="link_d2">
    <visual>
      <geometry>
        <mesh filename="package://abb_irb4400_support/meshes/irb4400/visual/link_d2.stl"/>
      </geometry>
      <material name="orange"/>
    </visual>
  </link>
  <joint name="joint_1" type="revolute">
    <parent link="base_link"/>
    <child link="link_1"/>
    <origin rpy="0 0 0" xyz="0 0 0"/>
    <axis xyz="0 0 1"/>
    <limit effort="0" lower="-2.8798" upper="2.8798" velocity="2.6180"/>
  </joint>
  <joint name="joint_2" type="revolute">
    <parent link="link_1"/>
    <child link="link_2"/>
    <origin rpy="0 0 0" xyz="0.200 0 0.680"/>
    <axis xyz="0 1 0"/>
    <limit effort="0" lower="-1.2217" upper="1.6755" velocity="2.0944"/>
  </joint>
  <joint name="joint_3" type="revolute">
    <parent link="link_2"/>
    <child link="link_3"/>
    <origin rpy="0 0 0" xyz="0 0 0.890"/>
    <axis xyz="0 1 0"/>
    <limit effort="0" lower="-1.0472" upper="1.1345" velocity="2.0944"/>
  </joint>
  <joint name="joint_4" type="revolute">
    <parent link="link_3"/>
    <child link="link_4"/>
    <origin rpy="0 0 0" xyz="0 0 0.150"/>
    <axis xyz="1 0 0"/>
    <limit effort="0" lower="-3.4907" upper="3.4907" velocity="3.9270"/>
  </joint>
  <joint name="joint_5" type="revolute">
    <parent link="link_4"/>
    <child link="link_5"/>
    <origin rpy="0 0 0" xyz="0.880 0 0"/>
    <axis xyz="0 1 0"/>
    <limit effort="0" lower="-2.0944" upper="2.0944" velocity="2.3633"/>
  </joint>
  <joint name="joint_6" type="revolute">
    <parent link="link_5"/>
    <child link="link_6"/>
    <origin rpy="0 0 0" xyz="0 0 0"/>
    <axis xyz="1 0 0"/>
    <limit effort="0" lower="-6.9813" upper="6.9813" velocity="5.7596"/>
  </joint>
  <joint name="joint_6-tool0" type="fixed">
    <parent link="link_6"/>
    <child link="tool0"/>
    <origin rpy="0 1.5708 0" xyz="0.140 0 0"/>
  </joint>
  <joint name="joint_d2" type="revolute">
    <parent link="link_1"/>
    <child link="link_d2"/>
    <origin rpy="0 -0.170 0" xyz="-0.365 -0.1895 0.405"/>
    <axis xyz="0 1 0"/>
    <mimic joint="joint_2" multiplier="-1.0" offset="0.0"/>
    <limit effort="0" lower="-1.2217" upper="1.6755" velocity="2.0944"/>
  </joint>
</robot>

