<?xml version="1.0" ?>
<!-- =================================================================================== -->
<!-- |    This document was autogenerated by xacro from irb_4400_l30.xacro             | -->
<!-- |    EDITING THIS FILE BY HAND IS NOT RECOMMENDED                                 | -->
<!-- =================================================================================== -->
<robot name="irb_4400_l30" xmlns:xacro="http://ros.org/wiki/xacro">
  <link name="base_link">
    <visual>
      <origin rpy="0 0 0" xyz="0 0 0"/>
      <geometry>
        <mesh filename="package://abb_common/meshes/irb_4400_l30/visual/base_link.STL"/>
      </geometry>
      <material name="abb_orange">
        <color rgba="1 0.43 0 1"/>
      </material>
    </visual>
    <collision>
      <geometry>
        <mesh filename="package://abb_common/meshes/irb_4400_l30/collision/base_link.STL"/>
      </geometry>
      <material name="yellow">
        <color rgba="0 1 1 1"/>
      </material>
    </collision>
  </link>
  <link name="link_1">
    <visual>
      <origin rpy="0 0 0" xyz="0 0 0"/>
      <geometry>
        <mesh filename="package://abb_common/meshes/irb_4400_l30/visual/link_1.STL"/>
      </geometry>
      <material name="abb_orange"/>
    </visual>
    <collision>
      <origin rpy="0 0 0" xyz="0 0 0"/>
      <geometry>
        <mesh filename="package://abb_common/meshes/irb_4400_l30/collision/link_1.STL"/>
      </geometry>
      <material name="yellow"/>
    </collision>
  </link>
  <link name="link_2">
    <visual>
      <origin rpy="0 0 0" xyz="0 0 0"/>
      <geometry>
        <mesh filename="package://abb_common/meshes/irb_4400_l30/visual/link_2.STL"/>
      </geometry>
      <material name="abb_orange"/>
    </visual>
    <collision>
      <origin rpy="0 0 0" xyz="0 0 0"/>
      <geometry>
        <mesh filename="package://abb_common/meshes/irb_4400_l30/collision/link_2.STL"/>
      </geometry>
      <material name="yellow"/>
    </collision>
  </link>
  <link name="link_3">
    <visual>
      <origin rpy="0 0 0" xyz="0 0 0"/>
      <geometry>
        <mesh filename="package://abb_common/meshes/irb_4400_l30/visual/link_3.STL"/>
      </geometry>
      <material name="abb_orange"/>
    </visual>
    <collision>
      <origin rpy="0 0 0" xyz="0 0 0"/>
      <geometry>
        <mesh filename="package://abb_common/meshes/irb_4400_l30/collision/link_3.STL"/>
      </geometry>
      <material name="yellow"/>
    </collision>
  </link>
  <link name="link_4">
    <visual>
      <origin rpy="0 0 0" xyz="0 0 0"/>
      <geometry>
        <mesh filename="package://abb_common/meshes/irb_4400_l30/visual/link_4.STL"/>
      </geometry>
      <material name="abb_orange"/>
    </visual>
    <collision>
      <origin rpy="0 0 0" xyz="0 0 0"/>
      <geometry>
        <mesh filename="package://abb_common/meshes/irb_4400_l30/collision/link_4.STL"/>
      </geometry>
      <material name="yellow"/>
    </collision>
  </link>
  <link name="link_5">
    <visual>
      <origin rpy="0 0 0" xyz="0 0 0"/>
      <geometry>
        <mesh filename="package://abb_common/meshes/irb_4400_l30/visual/link_5.STL"/>
      </geometry>
      <material name="abb_orange"/>
    </visual>
    <collision>
      <origin rpy="0 0 0" xyz="0 0 0"/>
      <geometry>
        <mesh filename="package://abb_common/meshes/irb_4400_l30/collision/link_5.STL"/>
      </geometry>
      <material name="yellow"/>
    </collision>
  </link>
  <link name="link_6">
    <visual>
      <origin rpy="0 0 0" xyz="0 0 0"/>
      <geometry>
        <mesh filename="package://abb_common/meshes/irb_4400_l30/visual/link_6.STL"/>
      </geometry>
      <material name="abb_orange"/>
    </visual>
    <collision>
      <origin rpy="0 0 0" xyz="0 0 0"/>
      <geometry>
        <mesh filename="package://abb_common/meshes/irb_4400_l30/collision/link_6.STL"/>
      </geometry>
      <material name="yellow"/>
    </collision>
  </link>
  <link name="tool0"/>
  <joint name="joint_1" type="revolute">
    <origin rpy="0 0 0" xyz="0 0 0"/>
    <parent link="base_link"/>
    <child link="link_1"/>
    <axis xyz="0 0 1"/>
    <limit effort="0" lower="-2.87" upper="2.87" velocity="1.00"/>
    <!--change from default-->
  </joint>
  <joint name="joint_2" type="revolute">
    <origin rpy="0 0 0" xyz="0.2 0 0.68"/>
    <parent link="link_1"/>
    <child link="link_2"/>
    <axis xyz="0 1 0"/>
    <limit effort="0" lower="-1.7453" upper="1.9199" velocity="1.00"/>
    <!--check limits and velocity-->
  </joint>
  <joint name="joint_3" type="revolute">
    <origin rpy="0 0 0" xyz="0 0 0.89"/>
    <parent link="link_2"/>
    <child link="link_3"/>
    <axis xyz="0 1 0"/>
    <limit effort="0" lower="-1.0472" upper="1.1345" velocity="2.618"/>
    <!--check limits and velocity-->
  </joint>
  <joint name="joint_4" type="revolute">
    <origin rpy="0 0 0" xyz="1.3809 0 0.15"/>
    <parent link="link_3"/>
    <child link="link_4"/>
    <axis xyz="1 0 0"/>
    <limit effort="0" lower="-3.49" upper="3.49" velocity="3.14"/>
    <!--check this-->
  </joint>
  <joint name="joint_5" type="revolute">
    <origin rpy="0 0 0" xyz="0 0 0"/>
    <parent link="link_4"/>
    <child link="link_5"/>
    <axis xyz="0 1 0"/>
    <limit effort="0" lower="-2.094" upper="2.094" velocity="3.14"/>
    <!--check this-->
  </joint>
  <joint name="joint_6" type="revolute">
    <origin rpy="0 0 0" xyz="0 0 0"/>
    <parent link="link_5"/>
    <child link="link_6"/>
    <axis xyz="1 0 0"/>
    <limit effort="0" lower="-6.98" upper="6.98" velocity="3.14"/>
    <!--check this-->
  </joint>
  <joint name="joint_6-tool0" type="fixed">
    <parent link="link_6"/>
    <child link="tool0"/>
    <origin rpy="0 0 0" xyz="0.1391 0 0"/>
  </joint>
</robot>

